[2021-06-21 17:50:21,340 | CRITICAL | ../../../../../opt/hostedtoolcache/Python/3.9.5/x64/lib/python3.9/site-packages/PyFunceble/cli/processes/workers/base.py:381@run | PPID2676:pyfunceble_tester_worker_1]:
Error while running target
Traceback (most recent call last):
  File "/opt/hostedtoolcache/Python/3.9.5/x64/lib/python3.9/site-packages/PyFunceble/cli/processes/workers/base.py", line 366, in run
    result = self.target(consumed)
  File "/opt/hostedtoolcache/Python/3.9.5/x64/lib/python3.9/site-packages/PyFunceble/cli/processes/workers/tester.py", line 275, in target
    self.testing_object.set_subject(test_dataset["idna_subject"])
  File "/opt/hostedtoolcache/Python/3.9.5/x64/lib/python3.9/site-packages/PyFunceble/checker/base.py", line 135, in wrapper
    return func(self, *args, **kwargs)  # pylint: disable=not-callable
  File "/opt/hostedtoolcache/Python/3.9.5/x64/lib/python3.9/site-packages/PyFunceble/checker/base.py", line 160, in wrapper
    result = func(self, *args, **kwargs)  # pylint: disable=not-callable
  File "/opt/hostedtoolcache/Python/3.9.5/x64/lib/python3.9/site-packages/PyFunceble/checker/availability/domain_and_ip.py", line 109, in query_status
    result = query_object.query_status()
  File "/opt/hostedtoolcache/Python/3.9.5/x64/lib/python3.9/site-packages/PyFunceble/checker/base.py", line 135, in wrapper
    return func(self, *args, **kwargs)  # pylint: disable=not-callable
  File "/opt/hostedtoolcache/Python/3.9.5/x64/lib/python3.9/site-packages/PyFunceble/checker/base.py", line 160, in wrapper
    result = func(self, *args, **kwargs)  # pylint: disable=not-callable
  File "/opt/hostedtoolcache/Python/3.9.5/x64/lib/python3.9/site-packages/PyFunceble/checker/availability/domain.py", line 179, in query_status
    ExtraRulesHandler(self.status).start()
  File "/opt/hostedtoolcache/Python/3.9.5/x64/lib/python3.9/site-packages/PyFunceble/checker/availability/extra_rules.py", line 129, in wrapper
    return func(self, *args, **kwargs)  # pylint: disable=not-callable
  File "/opt/hostedtoolcache/Python/3.9.5/x64/lib/python3.9/site-packages/PyFunceble/checker/availability/extra_rules.py", line 320, in start
    self.__handle_active2inactive()
  File "/opt/hostedtoolcache/Python/3.9.5/x64/lib/python3.9/site-packages/PyFunceble/checker/availability/extra_rules.py", line 301, in __handle_active2inactive
    self.__regex_registry_handler(self.regex_active2inactive)
  File "/opt/hostedtoolcache/Python/3.9.5/x64/lib/python3.9/site-packages/PyFunceble/checker/availability/extra_rules.py", line 218, in __regex_registry_handler
    element()
  File "/opt/hostedtoolcache/Python/3.9.5/x64/lib/python3.9/site-packages/PyFunceble/checker/availability/extra_rules.py", line 267, in __handle_blogspot
    if self.status.subject.starts("http:"):
AttributeError: 'str' object has no attribute 'starts'
[2021-06-21 18:21:39,018 | CRITICAL | ../../../../../opt/hostedtoolcache/Python/3.9.5/x64/lib/python3.9/site-packages/PyFunceble/cli/processes/workers/base.py:381@run | PPID2518:pyfunceble_tester_worker_1]:
Error while running target
Traceback (most recent call last):
  File "/opt/hostedtoolcache/Python/3.9.5/x64/lib/python3.9/site-packages/PyFunceble/cli/processes/workers/base.py", line 366, in run
    result = self.target(consumed)
  File "/opt/hostedtoolcache/Python/3.9.5/x64/lib/python3.9/site-packages/PyFunceble/cli/processes/workers/tester.py", line 275, in target
    self.testing_object.set_subject(test_dataset["idna_subject"])
  File "/opt/hostedtoolcache/Python/3.9.5/x64/lib/python3.9/site-packages/PyFunceble/checker/base.py", line 135, in wrapper
    return func(self, *args, **kwargs)  # pylint: disable=not-callable
  File "/opt/hostedtoolcache/Python/3.9.5/x64/lib/python3.9/site-packages/PyFunceble/checker/base.py", line 160, in wrapper
    result = func(self, *args, **kwargs)  # pylint: disable=not-callable
  File "/opt/hostedtoolcache/Python/3.9.5/x64/lib/python3.9/site-packages/PyFunceble/checker/availability/domain_and_ip.py", line 109, in query_status
    result = query_object.query_status()
  File "/opt/hostedtoolcache/Python/3.9.5/x64/lib/python3.9/site-packages/PyFunceble/checker/base.py", line 135, in wrapper
    return func(self, *args, **kwargs)  # pylint: disable=not-callable
  File "/opt/hostedtoolcache/Python/3.9.5/x64/lib/python3.9/site-packages/PyFunceble/checker/base.py", line 160, in wrapper
    result = func(self, *args, **kwargs)  # pylint: disable=not-callable
  File "/opt/hostedtoolcache/Python/3.9.5/x64/lib/python3.9/site-packages/PyFunceble/checker/availability/domain.py", line 179, in query_status
    ExtraRulesHandler(self.status).start()
  File "/opt/hostedtoolcache/Python/3.9.5/x64/lib/python3.9/site-packages/PyFunceble/checker/availability/extra_rules.py", line 129, in wrapper
    return func(self, *args, **kwargs)  # pylint: disable=not-callable
  File "/opt/hostedtoolcache/Python/3.9.5/x64/lib/python3.9/site-packages/PyFunceble/checker/availability/extra_rules.py", line 320, in start
    self.__handle_active2inactive()
  File "/opt/hostedtoolcache/Python/3.9.5/x64/lib/python3.9/site-packages/PyFunceble/checker/availability/extra_rules.py", line 301, in __handle_active2inactive
    self.__regex_registry_handler(self.regex_active2inactive)
  File "/opt/hostedtoolcache/Python/3.9.5/x64/lib/python3.9/site-packages/PyFunceble/checker/availability/extra_rules.py", line 218, in __regex_registry_handler
    element()
  File "/opt/hostedtoolcache/Python/3.9.5/x64/lib/python3.9/site-packages/PyFunceble/checker/availability/extra_rules.py", line 267, in __handle_blogspot
    if self.status.subject.starts("http:"):
AttributeError: 'str' object has no attribute 'starts'
[2021-06-21 18:26:34,100 | CRITICAL | ../../../../../opt/hostedtoolcache/Python/3.9.5/x64/lib/python3.9/site-packages/PyFunceble/cli/processes/workers/base.py:381@run | PPID2538:pyfunceble_tester_worker_1]:
Error while running target
Traceback (most recent call last):
  File "/opt/hostedtoolcache/Python/3.9.5/x64/lib/python3.9/site-packages/PyFunceble/cli/processes/workers/base.py", line 366, in run
    result = self.target(consumed)
  File "/opt/hostedtoolcache/Python/3.9.5/x64/lib/python3.9/site-packages/PyFunceble/cli/processes/workers/tester.py", line 275, in target
    self.testing_object.set_subject(test_dataset["idna_subject"])
  File "/opt/hostedtoolcache/Python/3.9.5/x64/lib/python3.9/site-packages/PyFunceble/checker/base.py", line 135, in wrapper
    return func(self, *args, **kwargs)  # pylint: disable=not-callable
  File "/opt/hostedtoolcache/Python/3.9.5/x64/lib/python3.9/site-packages/PyFunceble/checker/base.py", line 160, in wrapper
    result = func(self, *args, **kwargs)  # pylint: disable=not-callable
  File "/opt/hostedtoolcache/Python/3.9.5/x64/lib/python3.9/site-packages/PyFunceble/checker/availability/domain_and_ip.py", line 109, in query_status
    result = query_object.query_status()
  File "/opt/hostedtoolcache/Python/3.9.5/x64/lib/python3.9/site-packages/PyFunceble/checker/base.py", line 135, in wrapper
    return func(self, *args, **kwargs)  # pylint: disable=not-callable
  File "/opt/hostedtoolcache/Python/3.9.5/x64/lib/python3.9/site-packages/PyFunceble/checker/base.py", line 160, in wrapper
    result = func(self, *args, **kwargs)  # pylint: disable=not-callable
  File "/opt/hostedtoolcache/Python/3.9.5/x64/lib/python3.9/site-packages/PyFunceble/checker/availability/domain.py", line 179, in query_status
    ExtraRulesHandler(self.status).start()
  File "/opt/hostedtoolcache/Python/3.9.5/x64/lib/python3.9/site-packages/PyFunceble/checker/availability/extra_rules.py", line 129, in wrapper
    return func(self, *args, **kwargs)  # pylint: disable=not-callable
  File "/opt/hostedtoolcache/Python/3.9.5/x64/lib/python3.9/site-packages/PyFunceble/checker/availability/extra_rules.py", line 320, in start
    self.__handle_active2inactive()
  File "/opt/hostedtoolcache/Python/3.9.5/x64/lib/python3.9/site-packages/PyFunceble/checker/availability/extra_rules.py", line 301, in __handle_active2inactive
    self.__regex_registry_handler(self.regex_active2inactive)
  File "/opt/hostedtoolcache/Python/3.9.5/x64/lib/python3.9/site-packages/PyFunceble/checker/availability/extra_rules.py", line 218, in __regex_registry_handler
    element()
  File "/opt/hostedtoolcache/Python/3.9.5/x64/lib/python3.9/site-packages/PyFunceble/checker/availability/extra_rules.py", line 267, in __handle_blogspot
    if self.status.subject.starts("http:"):
AttributeError: 'str' object has no attribute 'starts'
[2021-06-21 19:01:59,379 | CRITICAL | ../../../../../opt/hostedtoolcache/Python/3.9.5/x64/lib/python3.9/site-packages/PyFunceble/cli/processes/workers/base.py:381@run | PPID1674:pyfunceble_tester_worker_1]:
Error while running target
Traceback (most recent call last):
  File "/opt/hostedtoolcache/Python/3.9.5/x64/lib/python3.9/site-packages/PyFunceble/cli/processes/workers/base.py", line 366, in run
    result = self.target(consumed)
  File "/opt/hostedtoolcache/Python/3.9.5/x64/lib/python3.9/site-packages/PyFunceble/cli/processes/workers/tester.py", line 275, in target
    self.testing_object.set_subject(test_dataset["idna_subject"])
  File "/opt/hostedtoolcache/Python/3.9.5/x64/lib/python3.9/site-packages/PyFunceble/checker/base.py", line 135, in wrapper
    return func(self, *args, **kwargs)  # pylint: disable=not-callable
  File "/opt/hostedtoolcache/Python/3.9.5/x64/lib/python3.9/site-packages/PyFunceble/checker/base.py", line 160, in wrapper
    result = func(self, *args, **kwargs)  # pylint: disable=not-callable
  File "/opt/hostedtoolcache/Python/3.9.5/x64/lib/python3.9/site-packages/PyFunceble/checker/availability/domain_and_ip.py", line 109, in query_status
    result = query_object.query_status()
  File "/opt/hostedtoolcache/Python/3.9.5/x64/lib/python3.9/site-packages/PyFunceble/checker/base.py", line 135, in wrapper
    return func(self, *args, **kwargs)  # pylint: disable=not-callable
  File "/opt/hostedtoolcache/Python/3.9.5/x64/lib/python3.9/site-packages/PyFunceble/checker/base.py", line 160, in wrapper
    result = func(self, *args, **kwargs)  # pylint: disable=not-callable
  File "/opt/hostedtoolcache/Python/3.9.5/x64/lib/python3.9/site-packages/PyFunceble/checker/availability/domain.py", line 179, in query_status
    ExtraRulesHandler(self.status).start()
  File "/opt/hostedtoolcache/Python/3.9.5/x64/lib/python3.9/site-packages/PyFunceble/checker/availability/extra_rules.py", line 129, in wrapper
    return func(self, *args, **kwargs)  # pylint: disable=not-callable
  File "/opt/hostedtoolcache/Python/3.9.5/x64/lib/python3.9/site-packages/PyFunceble/checker/availability/extra_rules.py", line 320, in start
    self.__handle_active2inactive()
  File "/opt/hostedtoolcache/Python/3.9.5/x64/lib/python3.9/site-packages/PyFunceble/checker/availability/extra_rules.py", line 301, in __handle_active2inactive
    self.__regex_registry_handler(self.regex_active2inactive)
  File "/opt/hostedtoolcache/Python/3.9.5/x64/lib/python3.9/site-packages/PyFunceble/checker/availability/extra_rules.py", line 218, in __regex_registry_handler
    element()
  File "/opt/hostedtoolcache/Python/3.9.5/x64/lib/python3.9/site-packages/PyFunceble/checker/availability/extra_rules.py", line 267, in __handle_blogspot
    if self.status.subject.starts("http:"):
AttributeError: 'str' object has no attribute 'starts'
[2021-06-21 21:30:50,766 | CRITICAL | ../../../../../opt/hostedtoolcache/Python/3.9.5/x64/lib/python3.9/site-packages/PyFunceble/cli/processes/workers/base.py:381@run | PPID2632:pyfunceble_tester_worker_1]:
Error while running target
Traceback (most recent call last):
  File "/opt/hostedtoolcache/Python/3.9.5/x64/lib/python3.9/site-packages/PyFunceble/cli/processes/workers/base.py", line 366, in run
    result = self.target(consumed)
  File "/opt/hostedtoolcache/Python/3.9.5/x64/lib/python3.9/site-packages/PyFunceble/cli/processes/workers/tester.py", line 275, in target
    self.testing_object.set_subject(test_dataset["idna_subject"])
  File "/opt/hostedtoolcache/Python/3.9.5/x64/lib/python3.9/site-packages/PyFunceble/checker/base.py", line 135, in wrapper
    return func(self, *args, **kwargs)  # pylint: disable=not-callable
  File "/opt/hostedtoolcache/Python/3.9.5/x64/lib/python3.9/site-packages/PyFunceble/checker/base.py", line 160, in wrapper
    result = func(self, *args, **kwargs)  # pylint: disable=not-callable
  File "/opt/hostedtoolcache/Python/3.9.5/x64/lib/python3.9/site-packages/PyFunceble/checker/availability/domain_and_ip.py", line 109, in query_status
    result = query_object.query_status()
  File "/opt/hostedtoolcache/Python/3.9.5/x64/lib/python3.9/site-packages/PyFunceble/checker/base.py", line 135, in wrapper
    return func(self, *args, **kwargs)  # pylint: disable=not-callable
  File "/opt/hostedtoolcache/Python/3.9.5/x64/lib/python3.9/site-packages/PyFunceble/checker/base.py", line 160, in wrapper
    result = func(self, *args, **kwargs)  # pylint: disable=not-callable
  File "/opt/hostedtoolcache/Python/3.9.5/x64/lib/python3.9/site-packages/PyFunceble/checker/availability/domain.py", line 179, in query_status
    ExtraRulesHandler(self.status).start()
  File "/opt/hostedtoolcache/Python/3.9.5/x64/lib/python3.9/site-packages/PyFunceble/checker/availability/extra_rules.py", line 129, in wrapper
    return func(self, *args, **kwargs)  # pylint: disable=not-callable
  File "/opt/hostedtoolcache/Python/3.9.5/x64/lib/python3.9/site-packages/PyFunceble/checker/availability/extra_rules.py", line 320, in start
    self.__handle_active2inactive()
  File "/opt/hostedtoolcache/Python/3.9.5/x64/lib/python3.9/site-packages/PyFunceble/checker/availability/extra_rules.py", line 301, in __handle_active2inactive
    self.__regex_registry_handler(self.regex_active2inactive)
  File "/opt/hostedtoolcache/Python/3.9.5/x64/lib/python3.9/site-packages/PyFunceble/checker/availability/extra_rules.py", line 218, in __regex_registry_handler
    element()
  File "/opt/hostedtoolcache/Python/3.9.5/x64/lib/python3.9/site-packages/PyFunceble/checker/availability/extra_rules.py", line 267, in __handle_blogspot
    if self.status.subject.starts("http:"):
AttributeError: 'str' object has no attribute 'starts'
[2021-06-21 22:02:35,374 | CRITICAL | ../../../../../opt/hostedtoolcache/Python/3.9.5/x64/lib/python3.9/site-packages/PyFunceble/cli/processes/workers/base.py:381@run | PPID1682:pyfunceble_tester_worker_1]:
Error while running target
Traceback (most recent call last):
  File "/opt/hostedtoolcache/Python/3.9.5/x64/lib/python3.9/site-packages/PyFunceble/cli/processes/workers/base.py", line 366, in run
    result = self.target(consumed)
  File "/opt/hostedtoolcache/Python/3.9.5/x64/lib/python3.9/site-packages/PyFunceble/cli/processes/workers/tester.py", line 275, in target
    self.testing_object.set_subject(test_dataset["idna_subject"])
  File "/opt/hostedtoolcache/Python/3.9.5/x64/lib/python3.9/site-packages/PyFunceble/checker/base.py", line 135, in wrapper
    return func(self, *args, **kwargs)  # pylint: disable=not-callable
  File "/opt/hostedtoolcache/Python/3.9.5/x64/lib/python3.9/site-packages/PyFunceble/checker/base.py", line 160, in wrapper
    result = func(self, *args, **kwargs)  # pylint: disable=not-callable
  File "/opt/hostedtoolcache/Python/3.9.5/x64/lib/python3.9/site-packages/PyFunceble/checker/availability/domain_and_ip.py", line 109, in query_status
    result = query_object.query_status()
  File "/opt/hostedtoolcache/Python/3.9.5/x64/lib/python3.9/site-packages/PyFunceble/checker/base.py", line 135, in wrapper
    return func(self, *args, **kwargs)  # pylint: disable=not-callable
  File "/opt/hostedtoolcache/Python/3.9.5/x64/lib/python3.9/site-packages/PyFunceble/checker/base.py", line 160, in wrapper
    result = func(self, *args, **kwargs)  # pylint: disable=not-callable
  File "/opt/hostedtoolcache/Python/3.9.5/x64/lib/python3.9/site-packages/PyFunceble/checker/availability/domain.py", line 179, in query_status
    ExtraRulesHandler(self.status).start()
  File "/opt/hostedtoolcache/Python/3.9.5/x64/lib/python3.9/site-packages/PyFunceble/checker/availability/extra_rules.py", line 129, in wrapper
    return func(self, *args, **kwargs)  # pylint: disable=not-callable
  File "/opt/hostedtoolcache/Python/3.9.5/x64/lib/python3.9/site-packages/PyFunceble/checker/availability/extra_rules.py", line 320, in start
    self.__handle_active2inactive()
  File "/opt/hostedtoolcache/Python/3.9.5/x64/lib/python3.9/site-packages/PyFunceble/checker/availability/extra_rules.py", line 301, in __handle_active2inactive
    self.__regex_registry_handler(self.regex_active2inactive)
  File "/opt/hostedtoolcache/Python/3.9.5/x64/lib/python3.9/site-packages/PyFunceble/checker/availability/extra_rules.py", line 218, in __regex_registry_handler
    element()
  File "/opt/hostedtoolcache/Python/3.9.5/x64/lib/python3.9/site-packages/PyFunceble/checker/availability/extra_rules.py", line 267, in __handle_blogspot
    if self.status.subject.starts("http:"):
AttributeError: 'str' object has no attribute 'starts'
[2021-06-21 23:54:13,138 | CRITICAL | ../../../../../opt/hostedtoolcache/Python/3.9.5/x64/lib/python3.9/site-packages/PyFunceble/cli/processes/workers/base.py:381@run | PPID2633:pyfunceble_tester_worker_1]:
Error while running target
Traceback (most recent call last):
  File "/opt/hostedtoolcache/Python/3.9.5/x64/lib/python3.9/site-packages/PyFunceble/cli/processes/workers/base.py", line 366, in run
    result = self.target(consumed)
  File "/opt/hostedtoolcache/Python/3.9.5/x64/lib/python3.9/site-packages/PyFunceble/cli/processes/workers/tester.py", line 275, in target
    self.testing_object.set_subject(test_dataset["idna_subject"])
  File "/opt/hostedtoolcache/Python/3.9.5/x64/lib/python3.9/site-packages/PyFunceble/checker/base.py", line 135, in wrapper
    return func(self, *args, **kwargs)  # pylint: disable=not-callable
  File "/opt/hostedtoolcache/Python/3.9.5/x64/lib/python3.9/site-packages/PyFunceble/checker/base.py", line 160, in wrapper
    result = func(self, *args, **kwargs)  # pylint: disable=not-callable
  File "/opt/hostedtoolcache/Python/3.9.5/x64/lib/python3.9/site-packages/PyFunceble/checker/availability/domain_and_ip.py", line 109, in query_status
    result = query_object.query_status()
  File "/opt/hostedtoolcache/Python/3.9.5/x64/lib/python3.9/site-packages/PyFunceble/checker/base.py", line 135, in wrapper
    return func(self, *args, **kwargs)  # pylint: disable=not-callable
  File "/opt/hostedtoolcache/Python/3.9.5/x64/lib/python3.9/site-packages/PyFunceble/checker/base.py", line 160, in wrapper
    result = func(self, *args, **kwargs)  # pylint: disable=not-callable
  File "/opt/hostedtoolcache/Python/3.9.5/x64/lib/python3.9/site-packages/PyFunceble/checker/availability/domain.py", line 179, in query_status
    ExtraRulesHandler(self.status).start()
  File "/opt/hostedtoolcache/Python/3.9.5/x64/lib/python3.9/site-packages/PyFunceble/checker/availability/extra_rules.py", line 129, in wrapper
    return func(self, *args, **kwargs)  # pylint: disable=not-callable
  File "/opt/hostedtoolcache/Python/3.9.5/x64/lib/python3.9/site-packages/PyFunceble/checker/availability/extra_rules.py", line 320, in start
    self.__handle_active2inactive()
  File "/opt/hostedtoolcache/Python/3.9.5/x64/lib/python3.9/site-packages/PyFunceble/checker/availability/extra_rules.py", line 301, in __handle_active2inactive
    self.__regex_registry_handler(self.regex_active2inactive)
  File "/opt/hostedtoolcache/Python/3.9.5/x64/lib/python3.9/site-packages/PyFunceble/checker/availability/extra_rules.py", line 218, in __regex_registry_handler
    element()
  File "/opt/hostedtoolcache/Python/3.9.5/x64/lib/python3.9/site-packages/PyFunceble/checker/availability/extra_rules.py", line 267, in __handle_blogspot
    if self.status.subject.starts("http:"):
AttributeError: 'str' object has no attribute 'starts'
[2021-06-22 00:55:56,960 | CRITICAL | ../../../../../opt/hostedtoolcache/Python/3.9.5/x64/lib/python3.9/site-packages/PyFunceble/cli/processes/workers/base.py:381@run | PPID2627:pyfunceble_tester_worker_1]:
Error while running target
Traceback (most recent call last):
  File "/opt/hostedtoolcache/Python/3.9.5/x64/lib/python3.9/site-packages/PyFunceble/cli/processes/workers/base.py", line 366, in run
    result = self.target(consumed)
  File "/opt/hostedtoolcache/Python/3.9.5/x64/lib/python3.9/site-packages/PyFunceble/cli/processes/workers/tester.py", line 275, in target
    self.testing_object.set_subject(test_dataset["idna_subject"])
  File "/opt/hostedtoolcache/Python/3.9.5/x64/lib/python3.9/site-packages/PyFunceble/checker/base.py", line 135, in wrapper
    return func(self, *args, **kwargs)  # pylint: disable=not-callable
  File "/opt/hostedtoolcache/Python/3.9.5/x64/lib/python3.9/site-packages/PyFunceble/checker/base.py", line 160, in wrapper
    result = func(self, *args, **kwargs)  # pylint: disable=not-callable
  File "/opt/hostedtoolcache/Python/3.9.5/x64/lib/python3.9/site-packages/PyFunceble/checker/availability/domain_and_ip.py", line 109, in query_status
    result = query_object.query_status()
  File "/opt/hostedtoolcache/Python/3.9.5/x64/lib/python3.9/site-packages/PyFunceble/checker/base.py", line 135, in wrapper
    return func(self, *args, **kwargs)  # pylint: disable=not-callable
  File "/opt/hostedtoolcache/Python/3.9.5/x64/lib/python3.9/site-packages/PyFunceble/checker/base.py", line 160, in wrapper
    result = func(self, *args, **kwargs)  # pylint: disable=not-callable
  File "/opt/hostedtoolcache/Python/3.9.5/x64/lib/python3.9/site-packages/PyFunceble/checker/availability/domain.py", line 179, in query_status
    ExtraRulesHandler(self.status).start()
  File "/opt/hostedtoolcache/Python/3.9.5/x64/lib/python3.9/site-packages/PyFunceble/checker/availability/extra_rules.py", line 129, in wrapper
    return func(self, *args, **kwargs)  # pylint: disable=not-callable
  File "/opt/hostedtoolcache/Python/3.9.5/x64/lib/python3.9/site-packages/PyFunceble/checker/availability/extra_rules.py", line 320, in start
    self.__handle_active2inactive()
  File "/opt/hostedtoolcache/Python/3.9.5/x64/lib/python3.9/site-packages/PyFunceble/checker/availability/extra_rules.py", line 301, in __handle_active2inactive
    self.__regex_registry_handler(self.regex_active2inactive)
  File "/opt/hostedtoolcache/Python/3.9.5/x64/lib/python3.9/site-packages/PyFunceble/checker/availability/extra_rules.py", line 218, in __regex_registry_handler
    element()
  File "/opt/hostedtoolcache/Python/3.9.5/x64/lib/python3.9/site-packages/PyFunceble/checker/availability/extra_rules.py", line 267, in __handle_blogspot
    if self.status.subject.starts("http:"):
AttributeError: 'str' object has no attribute 'starts'
[2021-06-22 02:15:53,216 | CRITICAL | ../../../../../opt/hostedtoolcache/Python/3.9.5/x64/lib/python3.9/site-packages/PyFunceble/cli/processes/workers/base.py:381@run | PPID2744:pyfunceble_tester_worker_1]:
Error while running target
Traceback (most recent call last):
  File "/opt/hostedtoolcache/Python/3.9.5/x64/lib/python3.9/site-packages/PyFunceble/cli/processes/workers/base.py", line 366, in run
    result = self.target(consumed)
  File "/opt/hostedtoolcache/Python/3.9.5/x64/lib/python3.9/site-packages/PyFunceble/cli/processes/workers/tester.py", line 275, in target
    self.testing_object.set_subject(test_dataset["idna_subject"])
  File "/opt/hostedtoolcache/Python/3.9.5/x64/lib/python3.9/site-packages/PyFunceble/checker/base.py", line 135, in wrapper
    return func(self, *args, **kwargs)  # pylint: disable=not-callable
  File "/opt/hostedtoolcache/Python/3.9.5/x64/lib/python3.9/site-packages/PyFunceble/checker/base.py", line 160, in wrapper
    result = func(self, *args, **kwargs)  # pylint: disable=not-callable
  File "/opt/hostedtoolcache/Python/3.9.5/x64/lib/python3.9/site-packages/PyFunceble/checker/availability/domain_and_ip.py", line 109, in query_status
    result = query_object.query_status()
  File "/opt/hostedtoolcache/Python/3.9.5/x64/lib/python3.9/site-packages/PyFunceble/checker/base.py", line 135, in wrapper
    return func(self, *args, **kwargs)  # pylint: disable=not-callable
  File "/opt/hostedtoolcache/Python/3.9.5/x64/lib/python3.9/site-packages/PyFunceble/checker/base.py", line 160, in wrapper
    result = func(self, *args, **kwargs)  # pylint: disable=not-callable
  File "/opt/hostedtoolcache/Python/3.9.5/x64/lib/python3.9/site-packages/PyFunceble/checker/availability/domain.py", line 179, in query_status
    ExtraRulesHandler(self.status).start()
  File "/opt/hostedtoolcache/Python/3.9.5/x64/lib/python3.9/site-packages/PyFunceble/checker/availability/extra_rules.py", line 129, in wrapper
    return func(self, *args, **kwargs)  # pylint: disable=not-callable
  File "/opt/hostedtoolcache/Python/3.9.5/x64/lib/python3.9/site-packages/PyFunceble/checker/availability/extra_rules.py", line 320, in start
    self.__handle_active2inactive()
  File "/opt/hostedtoolcache/Python/3.9.5/x64/lib/python3.9/site-packages/PyFunceble/checker/availability/extra_rules.py", line 301, in __handle_active2inactive
    self.__regex_registry_handler(self.regex_active2inactive)
  File "/opt/hostedtoolcache/Python/3.9.5/x64/lib/python3.9/site-packages/PyFunceble/checker/availability/extra_rules.py", line 218, in __regex_registry_handler
    element()
  File "/opt/hostedtoolcache/Python/3.9.5/x64/lib/python3.9/site-packages/PyFunceble/checker/availability/extra_rules.py", line 267, in __handle_blogspot
    if self.status.subject.starts("http:"):
AttributeError: 'str' object has no attribute 'starts'
[2021-06-22 03:00:45,647 | CRITICAL | ../../../../../opt/hostedtoolcache/Python/3.9.5/x64/lib/python3.9/site-packages/PyFunceble/cli/processes/workers/base.py:381@run | PPID1836:pyfunceble_tester_worker_1]:
Error while running target
Traceback (most recent call last):
  File "/opt/hostedtoolcache/Python/3.9.5/x64/lib/python3.9/site-packages/PyFunceble/cli/processes/workers/base.py", line 366, in run
    result = self.target(consumed)
  File "/opt/hostedtoolcache/Python/3.9.5/x64/lib/python3.9/site-packages/PyFunceble/cli/processes/workers/tester.py", line 275, in target
    self.testing_object.set_subject(test_dataset["idna_subject"])
  File "/opt/hostedtoolcache/Python/3.9.5/x64/lib/python3.9/site-packages/PyFunceble/checker/base.py", line 135, in wrapper
    return func(self, *args, **kwargs)  # pylint: disable=not-callable
  File "/opt/hostedtoolcache/Python/3.9.5/x64/lib/python3.9/site-packages/PyFunceble/checker/base.py", line 160, in wrapper
    result = func(self, *args, **kwargs)  # pylint: disable=not-callable
  File "/opt/hostedtoolcache/Python/3.9.5/x64/lib/python3.9/site-packages/PyFunceble/checker/availability/domain_and_ip.py", line 109, in query_status
    result = query_object.query_status()
  File "/opt/hostedtoolcache/Python/3.9.5/x64/lib/python3.9/site-packages/PyFunceble/checker/base.py", line 135, in wrapper
    return func(self, *args, **kwargs)  # pylint: disable=not-callable
  File "/opt/hostedtoolcache/Python/3.9.5/x64/lib/python3.9/site-packages/PyFunceble/checker/base.py", line 160, in wrapper
    result = func(self, *args, **kwargs)  # pylint: disable=not-callable
  File "/opt/hostedtoolcache/Python/3.9.5/x64/lib/python3.9/site-packages/PyFunceble/checker/availability/domain.py", line 179, in query_status
    ExtraRulesHandler(self.status).start()
  File "/opt/hostedtoolcache/Python/3.9.5/x64/lib/python3.9/site-packages/PyFunceble/checker/availability/extra_rules.py", line 129, in wrapper
    return func(self, *args, **kwargs)  # pylint: disable=not-callable
  File "/opt/hostedtoolcache/Python/3.9.5/x64/lib/python3.9/site-packages/PyFunceble/checker/availability/extra_rules.py", line 320, in start
    self.__handle_active2inactive()
  File "/opt/hostedtoolcache/Python/3.9.5/x64/lib/python3.9/site-packages/PyFunceble/checker/availability/extra_rules.py", line 301, in __handle_active2inactive
    self.__regex_registry_handler(self.regex_active2inactive)
  File "/opt/hostedtoolcache/Python/3.9.5/x64/lib/python3.9/site-packages/PyFunceble/checker/availability/extra_rules.py", line 218, in __regex_registry_handler
    element()
  File "/opt/hostedtoolcache/Python/3.9.5/x64/lib/python3.9/site-packages/PyFunceble/checker/availability/extra_rules.py", line 267, in __handle_blogspot
    if self.status.subject.starts("http:"):
AttributeError: 'str' object has no attribute 'starts'
[2021-06-22 04:34:53,636 | CRITICAL | ../../../../../opt/hostedtoolcache/Python/3.9.5/x64/lib/python3.9/site-packages/PyFunceble/cli/processes/workers/base.py:381@run | PPID2482:pyfunceble_tester_worker_1]:
Error while running target
Traceback (most recent call last):
  File "/opt/hostedtoolcache/Python/3.9.5/x64/lib/python3.9/site-packages/PyFunceble/cli/processes/workers/base.py", line 366, in run
    result = self.target(consumed)
  File "/opt/hostedtoolcache/Python/3.9.5/x64/lib/python3.9/site-packages/PyFunceble/cli/processes/workers/tester.py", line 275, in target
    self.testing_object.set_subject(test_dataset["idna_subject"])
  File "/opt/hostedtoolcache/Python/3.9.5/x64/lib/python3.9/site-packages/PyFunceble/checker/base.py", line 135, in wrapper
    return func(self, *args, **kwargs)  # pylint: disable=not-callable
  File "/opt/hostedtoolcache/Python/3.9.5/x64/lib/python3.9/site-packages/PyFunceble/checker/base.py", line 160, in wrapper
    result = func(self, *args, **kwargs)  # pylint: disable=not-callable
  File "/opt/hostedtoolcache/Python/3.9.5/x64/lib/python3.9/site-packages/PyFunceble/checker/availability/domain_and_ip.py", line 109, in query_status
    result = query_object.query_status()
  File "/opt/hostedtoolcache/Python/3.9.5/x64/lib/python3.9/site-packages/PyFunceble/checker/base.py", line 135, in wrapper
    return func(self, *args, **kwargs)  # pylint: disable=not-callable
  File "/opt/hostedtoolcache/Python/3.9.5/x64/lib/python3.9/site-packages/PyFunceble/checker/base.py", line 160, in wrapper
    result = func(self, *args, **kwargs)  # pylint: disable=not-callable
  File "/opt/hostedtoolcache/Python/3.9.5/x64/lib/python3.9/site-packages/PyFunceble/checker/availability/domain.py", line 179, in query_status
    ExtraRulesHandler(self.status).start()
  File "/opt/hostedtoolcache/Python/3.9.5/x64/lib/python3.9/site-packages/PyFunceble/checker/availability/extra_rules.py", line 129, in wrapper
    return func(self, *args, **kwargs)  # pylint: disable=not-callable
  File "/opt/hostedtoolcache/Python/3.9.5/x64/lib/python3.9/site-packages/PyFunceble/checker/availability/extra_rules.py", line 320, in start
    self.__handle_active2inactive()
  File "/opt/hostedtoolcache/Python/3.9.5/x64/lib/python3.9/site-packages/PyFunceble/checker/availability/extra_rules.py", line 301, in __handle_active2inactive
    self.__regex_registry_handler(self.regex_active2inactive)
  File "/opt/hostedtoolcache/Python/3.9.5/x64/lib/python3.9/site-packages/PyFunceble/checker/availability/extra_rules.py", line 218, in __regex_registry_handler
    element()
  File "/opt/hostedtoolcache/Python/3.9.5/x64/lib/python3.9/site-packages/PyFunceble/checker/availability/extra_rules.py", line 267, in __handle_blogspot
    if self.status.subject.starts("http:"):
AttributeError: 'str' object has no attribute 'starts'
[2021-06-22 07:59:41,764 | CRITICAL | ../../../../../opt/hostedtoolcache/Python/3.9.5/x64/lib/python3.9/site-packages/PyFunceble/cli/processes/workers/base.py:381@run | PPID1676:pyfunceble_tester_worker_1]:
Error while running target
Traceback (most recent call last):
  File "/opt/hostedtoolcache/Python/3.9.5/x64/lib/python3.9/site-packages/PyFunceble/cli/processes/workers/base.py", line 366, in run
    result = self.target(consumed)
  File "/opt/hostedtoolcache/Python/3.9.5/x64/lib/python3.9/site-packages/PyFunceble/cli/processes/workers/tester.py", line 275, in target
    self.testing_object.set_subject(test_dataset["idna_subject"])
  File "/opt/hostedtoolcache/Python/3.9.5/x64/lib/python3.9/site-packages/PyFunceble/checker/base.py", line 135, in wrapper
    return func(self, *args, **kwargs)  # pylint: disable=not-callable
  File "/opt/hostedtoolcache/Python/3.9.5/x64/lib/python3.9/site-packages/PyFunceble/checker/base.py", line 160, in wrapper
    result = func(self, *args, **kwargs)  # pylint: disable=not-callable
  File "/opt/hostedtoolcache/Python/3.9.5/x64/lib/python3.9/site-packages/PyFunceble/checker/availability/domain_and_ip.py", line 109, in query_status
    result = query_object.query_status()
  File "/opt/hostedtoolcache/Python/3.9.5/x64/lib/python3.9/site-packages/PyFunceble/checker/base.py", line 135, in wrapper
    return func(self, *args, **kwargs)  # pylint: disable=not-callable
  File "/opt/hostedtoolcache/Python/3.9.5/x64/lib/python3.9/site-packages/PyFunceble/checker/base.py", line 160, in wrapper
    result = func(self, *args, **kwargs)  # pylint: disable=not-callable
  File "/opt/hostedtoolcache/Python/3.9.5/x64/lib/python3.9/site-packages/PyFunceble/checker/availability/domain.py", line 179, in query_status
    ExtraRulesHandler(self.status).start()
  File "/opt/hostedtoolcache/Python/3.9.5/x64/lib/python3.9/site-packages/PyFunceble/checker/availability/extra_rules.py", line 129, in wrapper
    return func(self, *args, **kwargs)  # pylint: disable=not-callable
  File "/opt/hostedtoolcache/Python/3.9.5/x64/lib/python3.9/site-packages/PyFunceble/checker/availability/extra_rules.py", line 320, in start
    self.__handle_active2inactive()
  File "/opt/hostedtoolcache/Python/3.9.5/x64/lib/python3.9/site-packages/PyFunceble/checker/availability/extra_rules.py", line 301, in __handle_active2inactive
    self.__regex_registry_handler(self.regex_active2inactive)
  File "/opt/hostedtoolcache/Python/3.9.5/x64/lib/python3.9/site-packages/PyFunceble/checker/availability/extra_rules.py", line 218, in __regex_registry_handler
    element()
  File "/opt/hostedtoolcache/Python/3.9.5/x64/lib/python3.9/site-packages/PyFunceble/checker/availability/extra_rules.py", line 267, in __handle_blogspot
    if self.status.subject.starts("http:"):
AttributeError: 'str' object has no attribute 'starts'
[2021-12-21 07:32:40,472 | CRITICAL | ../../home/joakim/.local/lib/python3.10/site-packages/PyFunceble/cli/system/launcher.py:978@start | PPID73531:MainProcess]:
Fatal error.
Traceback (most recent call last):
  File "/home/joakim/.local/lib/python3.10/site-packages/pymysql/connections.py", line 756, in _write_bytes
    self._sock.sendall(data)
ConnectionResetError: [Errno 104] Connection reset by peer

During handling of the above exception, another exception occurred:

Traceback (most recent call last):
  File "/home/joakim/.local/lib/python3.10/site-packages/sqlalchemy/engine/base.py", line 1802, in _execute_context
    self.dialect.do_execute(
  File "/home/joakim/.local/lib/python3.10/site-packages/sqlalchemy/engine/default.py", line 732, in do_execute
    cursor.execute(statement, parameters)
  File "/home/joakim/.local/lib/python3.10/site-packages/pymysql/cursors.py", line 148, in execute
    result = self._query(query)
  File "/home/joakim/.local/lib/python3.10/site-packages/pymysql/cursors.py", line 310, in _query
    conn.query(q)
  File "/home/joakim/.local/lib/python3.10/site-packages/pymysql/connections.py", line 547, in query
    self._execute_command(COMMAND.COM_QUERY, sql)
  File "/home/joakim/.local/lib/python3.10/site-packages/pymysql/connections.py", line 814, in _execute_command
    self._write_bytes(packet)
  File "/home/joakim/.local/lib/python3.10/site-packages/pymysql/connections.py", line 759, in _write_bytes
    raise err.OperationalError(
pymysql.err.OperationalError: (2006, "MySQL server has gone away (ConnectionResetError(104, 'Connection reset by peer'))")

The above exception was the direct cause of the following exception:

Traceback (most recent call last):
  File "/home/joakim/.local/lib/python3.10/site-packages/PyFunceble/cli/system/launcher.py", line 974, in start
    self.run_standard_end_instructions()
  File "/home/joakim/.local/lib/python3.10/site-packages/PyFunceble/cli/system/launcher.py", line 838, in run_standard_end_instructions
    self.remove_unwanted_files()
  File "/home/joakim/.local/lib/python3.10/site-packages/PyFunceble/cli/system/launcher.py", line 816, in remove_unwanted_files
    remove_continue_dataset(protocol)
  File "/home/joakim/.local/lib/python3.10/site-packages/PyFunceble/cli/system/launcher.py", line 788, in remove_continue_dataset
    self.continue_dataset.cleanup(  # pylint: disable=unexpected-keyword-arg
  File "/home/joakim/.local/lib/python3.10/site-packages/PyFunceble/dataset/db_base.py", line 104, in wrapper
    return func(self, *args, **kwargs)  # pylint: disable=not-callable
  File "/home/joakim/.local/lib/python3.10/site-packages/PyFunceble/dataset/autocontinue/mariadb.py", line 84, in cleanup
    self.db_session.query(self.ORM_OBJ).filter(
  File "/home/joakim/.local/lib/python3.10/site-packages/sqlalchemy/orm/query.py", line 3191, in delete
    result = self.session.execute(
  File "/home/joakim/.local/lib/python3.10/site-packages/sqlalchemy/orm/session.py", line 1692, in execute
    result = conn._execute_20(statement, params or {}, execution_options)
  File "/home/joakim/.local/lib/python3.10/site-packages/sqlalchemy/engine/base.py", line 1614, in _execute_20
    return meth(self, args_10style, kwargs_10style, execution_options)
  File "/home/joakim/.local/lib/python3.10/site-packages/sqlalchemy/sql/elements.py", line 325, in _execute_on_connection
    return connection._execute_clauseelement(
  File "/home/joakim/.local/lib/python3.10/site-packages/sqlalchemy/engine/base.py", line 1481, in _execute_clauseelement
    ret = self._execute_context(
  File "/home/joakim/.local/lib/python3.10/site-packages/sqlalchemy/engine/base.py", line 1845, in _execute_context
    self._handle_dbapi_exception(
  File "/home/joakim/.local/lib/python3.10/site-packages/sqlalchemy/engine/base.py", line 2026, in _handle_dbapi_exception
    util.raise_(
  File "/home/joakim/.local/lib/python3.10/site-packages/sqlalchemy/util/compat.py", line 207, in raise_
    raise exception
  File "/home/joakim/.local/lib/python3.10/site-packages/sqlalchemy/engine/base.py", line 1802, in _execute_context
    self.dialect.do_execute(
  File "/home/joakim/.local/lib/python3.10/site-packages/sqlalchemy/engine/default.py", line 732, in do_execute
    cursor.execute(statement, parameters)
  File "/home/joakim/.local/lib/python3.10/site-packages/pymysql/cursors.py", line 148, in execute
    result = self._query(query)
  File "/home/joakim/.local/lib/python3.10/site-packages/pymysql/cursors.py", line 310, in _query
    conn.query(q)
  File "/home/joakim/.local/lib/python3.10/site-packages/pymysql/connections.py", line 547, in query
    self._execute_command(COMMAND.COM_QUERY, sql)
  File "/home/joakim/.local/lib/python3.10/site-packages/pymysql/connections.py", line 814, in _execute_command
    self._write_bytes(packet)
  File "/home/joakim/.local/lib/python3.10/site-packages/pymysql/connections.py", line 759, in _write_bytes
    raise err.OperationalError(
sqlalchemy.exc.OperationalError: (pymysql.err.OperationalError) (2006, "MySQL server has gone away (ConnectionResetError(104, 'Connection reset by peer'))")
[SQL: DELETE FROM pyfunceble_continue WHERE pyfunceble_continue.session_id = %(session_id_1)s]
[parameters: {'session_id_1': '7a86375ad4e0b934c4d2db27'}]
(Background on this error at: https://sqlalche.me/e/14/e3q8)
[2022-03-18 17:40:51,042 | CRITICAL | ../../home/joakim/.local/lib/python3.10/site-packages/PyFunceble/cli/processes/workers/base.py:388@run | PPID9967:pyfunceble_tester_worker_13]:
Error while running target
Traceback (most recent call last):
  File "/home/joakim/.local/lib/python3.10/site-packages/PyFunceble/cli/processes/workers/base.py", line 373, in run
    result = self.target(consumed)
  File "/home/joakim/.local/lib/python3.10/site-packages/PyFunceble/cli/processes/workers/tester.py", line 292, in target
    .query_status()
  File "/home/joakim/.local/lib/python3.10/site-packages/PyFunceble/checker/base.py", line 157, in wrapper
    return func(self, *args, **kwargs)  # pylint: disable=not-callable
  File "/home/joakim/.local/lib/python3.10/site-packages/PyFunceble/checker/base.py", line 182, in wrapper
    result = func(self, *args, **kwargs)  # pylint: disable=not-callable
  File "/home/joakim/.local/lib/python3.10/site-packages/PyFunceble/checker/availability/domain_and_ip.py", line 109, in query_status
    result = query_object.query_status()
  File "/home/joakim/.local/lib/python3.10/site-packages/PyFunceble/checker/base.py", line 157, in wrapper
    return func(self, *args, **kwargs)  # pylint: disable=not-callable
  File "/home/joakim/.local/lib/python3.10/site-packages/PyFunceble/checker/base.py", line 182, in wrapper
    result = func(self, *args, **kwargs)  # pylint: disable=not-callable
  File "/home/joakim/.local/lib/python3.10/site-packages/PyFunceble/checker/availability/domain.py", line 168, in query_status
    self.try_to_query_status_from_http_status_code()
  File "/home/joakim/.local/lib/python3.10/site-packages/PyFunceble/checker/availability/base.py", line 900, in try_to_query_status_from_http_status_code
    lookup_result = self.http_status_code_query_tool.get_status_code()
  File "/home/joakim/.local/lib/python3.10/site-packages/PyFunceble/query/http_status_code.py", line 122, in wrapper
    return func(self, *args, **kwargs)  # pylint: disable=not-callable
  File "/home/joakim/.local/lib/python3.10/site-packages/PyFunceble/query/http_status_code.py", line 337, in get_status_code
    req = PyFunceble.factory.Requester.get(
  File "/home/joakim/.local/lib/python3.10/site-packages/PyFunceble/query/requests/requester.py", line 213, in wrapper
    req = getattr(self.session, verb.lower())(*args, **kwargs)
  File "/home/joakim/.local/lib/python3.10/site-packages/requests/sessions.py", line 542, in get
    return self.request('GET', url, **kwargs)
  File "/home/joakim/.local/lib/python3.10/site-packages/requests/sessions.py", line 529, in request
    resp = self.send(prep, **send_kwargs)
  File "/home/joakim/.local/lib/python3.10/site-packages/requests/sessions.py", line 645, in send
    r = adapter.send(request, **kwargs)
  File "/home/joakim/.local/lib/python3.10/site-packages/PyFunceble/query/requests/adapter/http.py", line 99, in send
    kwargs["proxies"] = self.fetch_proxy_from_pattern(parsed_url.hostname)
  File "/home/joakim/.local/lib/python3.10/site-packages/PyFunceble/query/requests/adapter/base.py", line 177, in fetch_proxy_from_pattern
    extension = self.extract_extension(subject)
  File "/home/joakim/.local/lib/python3.10/site-packages/PyFunceble/query/requests/adapter/base.py", line 133, in extract_extension
    last_point = subject.rindex(".")
ValueError: substring not found
[2022-03-18 17:43:09,623 | CRITICAL | ../../home/joakim/.local/lib/python3.10/site-packages/PyFunceble/cli/processes/workers/base.py:388@run | PPID9976:pyfunceble_tester_worker_20]:
Error while running target
Traceback (most recent call last):
  File "/home/joakim/.local/lib/python3.10/site-packages/PyFunceble/cli/processes/workers/base.py", line 373, in run
    result = self.target(consumed)
  File "/home/joakim/.local/lib/python3.10/site-packages/PyFunceble/cli/processes/workers/tester.py", line 292, in target
    .query_status()
  File "/home/joakim/.local/lib/python3.10/site-packages/PyFunceble/checker/base.py", line 157, in wrapper
    return func(self, *args, **kwargs)  # pylint: disable=not-callable
  File "/home/joakim/.local/lib/python3.10/site-packages/PyFunceble/checker/base.py", line 182, in wrapper
    result = func(self, *args, **kwargs)  # pylint: disable=not-callable
  File "/home/joakim/.local/lib/python3.10/site-packages/PyFunceble/checker/availability/domain_and_ip.py", line 109, in query_status
    result = query_object.query_status()
  File "/home/joakim/.local/lib/python3.10/site-packages/PyFunceble/checker/base.py", line 157, in wrapper
    return func(self, *args, **kwargs)  # pylint: disable=not-callable
  File "/home/joakim/.local/lib/python3.10/site-packages/PyFunceble/checker/base.py", line 182, in wrapper
    result = func(self, *args, **kwargs)  # pylint: disable=not-callable
  File "/home/joakim/.local/lib/python3.10/site-packages/PyFunceble/checker/availability/domain.py", line 168, in query_status
    self.try_to_query_status_from_http_status_code()
  File "/home/joakim/.local/lib/python3.10/site-packages/PyFunceble/checker/availability/base.py", line 900, in try_to_query_status_from_http_status_code
    lookup_result = self.http_status_code_query_tool.get_status_code()
  File "/home/joakim/.local/lib/python3.10/site-packages/PyFunceble/query/http_status_code.py", line 122, in wrapper
    return func(self, *args, **kwargs)  # pylint: disable=not-callable
  File "/home/joakim/.local/lib/python3.10/site-packages/PyFunceble/query/http_status_code.py", line 337, in get_status_code
    req = PyFunceble.factory.Requester.get(
  File "/home/joakim/.local/lib/python3.10/site-packages/PyFunceble/query/requests/requester.py", line 213, in wrapper
    req = getattr(self.session, verb.lower())(*args, **kwargs)
  File "/home/joakim/.local/lib/python3.10/site-packages/requests/sessions.py", line 542, in get
    return self.request('GET', url, **kwargs)
  File "/home/joakim/.local/lib/python3.10/site-packages/requests/sessions.py", line 529, in request
    resp = self.send(prep, **send_kwargs)
  File "/home/joakim/.local/lib/python3.10/site-packages/requests/sessions.py", line 645, in send
    r = adapter.send(request, **kwargs)
  File "/home/joakim/.local/lib/python3.10/site-packages/PyFunceble/query/requests/adapter/http.py", line 99, in send
    kwargs["proxies"] = self.fetch_proxy_from_pattern(parsed_url.hostname)
  File "/home/joakim/.local/lib/python3.10/site-packages/PyFunceble/query/requests/adapter/base.py", line 177, in fetch_proxy_from_pattern
    extension = self.extract_extension(subject)
  File "/home/joakim/.local/lib/python3.10/site-packages/PyFunceble/query/requests/adapter/base.py", line 133, in extract_extension
    last_point = subject.rindex(".")
ValueError: substring not found
[2022-03-18 19:28:24,372 | CRITICAL | ../../home/joakim/.local/lib/python3.10/site-packages/PyFunceble/cli/processes/workers/base.py:388@run | PPID9983:pyfunceble_tester_worker_24]:
Error while running target
Traceback (most recent call last):
  File "/home/joakim/.local/lib/python3.10/site-packages/PyFunceble/cli/processes/workers/base.py", line 373, in run
    result = self.target(consumed)
  File "/home/joakim/.local/lib/python3.10/site-packages/PyFunceble/cli/processes/workers/tester.py", line 292, in target
    .query_status()
  File "/home/joakim/.local/lib/python3.10/site-packages/PyFunceble/checker/base.py", line 157, in wrapper
    return func(self, *args, **kwargs)  # pylint: disable=not-callable
  File "/home/joakim/.local/lib/python3.10/site-packages/PyFunceble/checker/base.py", line 182, in wrapper
    result = func(self, *args, **kwargs)  # pylint: disable=not-callable
  File "/home/joakim/.local/lib/python3.10/site-packages/PyFunceble/checker/availability/domain_and_ip.py", line 109, in query_status
    result = query_object.query_status()
  File "/home/joakim/.local/lib/python3.10/site-packages/PyFunceble/checker/base.py", line 157, in wrapper
    return func(self, *args, **kwargs)  # pylint: disable=not-callable
  File "/home/joakim/.local/lib/python3.10/site-packages/PyFunceble/checker/base.py", line 182, in wrapper
    result = func(self, *args, **kwargs)  # pylint: disable=not-callable
  File "/home/joakim/.local/lib/python3.10/site-packages/PyFunceble/checker/availability/domain.py", line 168, in query_status
    self.try_to_query_status_from_http_status_code()
  File "/home/joakim/.local/lib/python3.10/site-packages/PyFunceble/checker/availability/base.py", line 900, in try_to_query_status_from_http_status_code
    lookup_result = self.http_status_code_query_tool.get_status_code()
  File "/home/joakim/.local/lib/python3.10/site-packages/PyFunceble/query/http_status_code.py", line 122, in wrapper
    return func(self, *args, **kwargs)  # pylint: disable=not-callable
  File "/home/joakim/.local/lib/python3.10/site-packages/PyFunceble/query/http_status_code.py", line 337, in get_status_code
    req = PyFunceble.factory.Requester.get(
  File "/home/joakim/.local/lib/python3.10/site-packages/PyFunceble/query/requests/requester.py", line 213, in wrapper
    req = getattr(self.session, verb.lower())(*args, **kwargs)
  File "/home/joakim/.local/lib/python3.10/site-packages/requests/sessions.py", line 542, in get
    return self.request('GET', url, **kwargs)
  File "/home/joakim/.local/lib/python3.10/site-packages/requests/sessions.py", line 529, in request
    resp = self.send(prep, **send_kwargs)
  File "/home/joakim/.local/lib/python3.10/site-packages/requests/sessions.py", line 645, in send
    r = adapter.send(request, **kwargs)
  File "/home/joakim/.local/lib/python3.10/site-packages/PyFunceble/query/requests/adapter/http.py", line 99, in send
    kwargs["proxies"] = self.fetch_proxy_from_pattern(parsed_url.hostname)
  File "/home/joakim/.local/lib/python3.10/site-packages/PyFunceble/query/requests/adapter/base.py", line 177, in fetch_proxy_from_pattern
    extension = self.extract_extension(subject)
  File "/home/joakim/.local/lib/python3.10/site-packages/PyFunceble/query/requests/adapter/base.py", line 133, in extract_extension
    last_point = subject.rindex(".")
ValueError: substring not found
[2022-03-19 15:10:10,044 | CRITICAL | ../../home/joakim/.local/lib/python3.10/site-packages/PyFunceble/cli/processes/workers/base.py:388@run | PPID9984:pyfunceble_tester_worker_25]:
Error while running target
Traceback (most recent call last):
  File "/home/joakim/.local/lib/python3.10/site-packages/PyFunceble/cli/processes/workers/base.py", line 373, in run
    result = self.target(consumed)
  File "/home/joakim/.local/lib/python3.10/site-packages/PyFunceble/cli/processes/workers/tester.py", line 292, in target
    .query_status()
  File "/home/joakim/.local/lib/python3.10/site-packages/PyFunceble/checker/base.py", line 157, in wrapper
    return func(self, *args, **kwargs)  # pylint: disable=not-callable
  File "/home/joakim/.local/lib/python3.10/site-packages/PyFunceble/checker/base.py", line 182, in wrapper
    result = func(self, *args, **kwargs)  # pylint: disable=not-callable
  File "/home/joakim/.local/lib/python3.10/site-packages/PyFunceble/checker/availability/domain_and_ip.py", line 109, in query_status
    result = query_object.query_status()
  File "/home/joakim/.local/lib/python3.10/site-packages/PyFunceble/checker/base.py", line 157, in wrapper
    return func(self, *args, **kwargs)  # pylint: disable=not-callable
  File "/home/joakim/.local/lib/python3.10/site-packages/PyFunceble/checker/base.py", line 182, in wrapper
    result = func(self, *args, **kwargs)  # pylint: disable=not-callable
  File "/home/joakim/.local/lib/python3.10/site-packages/PyFunceble/checker/availability/domain.py", line 168, in query_status
    self.try_to_query_status_from_http_status_code()
  File "/home/joakim/.local/lib/python3.10/site-packages/PyFunceble/checker/availability/base.py", line 900, in try_to_query_status_from_http_status_code
    lookup_result = self.http_status_code_query_tool.get_status_code()
  File "/home/joakim/.local/lib/python3.10/site-packages/PyFunceble/query/http_status_code.py", line 122, in wrapper
    return func(self, *args, **kwargs)  # pylint: disable=not-callable
  File "/home/joakim/.local/lib/python3.10/site-packages/PyFunceble/query/http_status_code.py", line 337, in get_status_code
    req = PyFunceble.factory.Requester.get(
  File "/home/joakim/.local/lib/python3.10/site-packages/PyFunceble/query/requests/requester.py", line 213, in wrapper
    req = getattr(self.session, verb.lower())(*args, **kwargs)
  File "/home/joakim/.local/lib/python3.10/site-packages/requests/sessions.py", line 542, in get
    return self.request('GET', url, **kwargs)
  File "/home/joakim/.local/lib/python3.10/site-packages/requests/sessions.py", line 529, in request
    resp = self.send(prep, **send_kwargs)
  File "/home/joakim/.local/lib/python3.10/site-packages/requests/sessions.py", line 667, in send
    history = [resp for resp in gen]
  File "/home/joakim/.local/lib/python3.10/site-packages/requests/sessions.py", line 667, in <listcomp>
    history = [resp for resp in gen]
  File "/home/joakim/.local/lib/python3.10/site-packages/requests/sessions.py", line 237, in resolve_redirects
    resp = self.send(
  File "/home/joakim/.local/lib/python3.10/site-packages/requests/sessions.py", line 645, in send
    r = adapter.send(request, **kwargs)
  File "/home/joakim/.local/lib/python3.10/site-packages/PyFunceble/query/requests/adapter/https.py", line 99, in send
    kwargs["proxies"] = self.fetch_proxy_from_pattern(parsed_url.hostname)
  File "/home/joakim/.local/lib/python3.10/site-packages/PyFunceble/query/requests/adapter/base.py", line 172, in fetch_proxy_from_pattern
    raise TypeError(f"<subject> should be {str}, type(subject) given.")
TypeError: <subject> should be <class 'str'>, type(subject) given.
[2022-03-20 20:38:15,561 | CRITICAL | ../../home/joakim/.local/lib/python3.10/site-packages/PyFunceble/cli/processes/workers/base.py:388@run | PPID9957:pyfunceble_tester_worker_6]:
Error while running target
Traceback (most recent call last):
  File "/home/joakim/.local/lib/python3.10/site-packages/PyFunceble/cli/processes/workers/base.py", line 373, in run
    result = self.target(consumed)
  File "/home/joakim/.local/lib/python3.10/site-packages/PyFunceble/cli/processes/workers/tester.py", line 292, in target
    .query_status()
  File "/home/joakim/.local/lib/python3.10/site-packages/PyFunceble/checker/base.py", line 157, in wrapper
    return func(self, *args, **kwargs)  # pylint: disable=not-callable
  File "/home/joakim/.local/lib/python3.10/site-packages/PyFunceble/checker/base.py", line 182, in wrapper
    result = func(self, *args, **kwargs)  # pylint: disable=not-callable
  File "/home/joakim/.local/lib/python3.10/site-packages/PyFunceble/checker/availability/domain_and_ip.py", line 109, in query_status
    result = query_object.query_status()
  File "/home/joakim/.local/lib/python3.10/site-packages/PyFunceble/checker/base.py", line 157, in wrapper
    return func(self, *args, **kwargs)  # pylint: disable=not-callable
  File "/home/joakim/.local/lib/python3.10/site-packages/PyFunceble/checker/base.py", line 182, in wrapper
    result = func(self, *args, **kwargs)  # pylint: disable=not-callable
  File "/home/joakim/.local/lib/python3.10/site-packages/PyFunceble/checker/availability/domain.py", line 168, in query_status
    self.try_to_query_status_from_http_status_code()
  File "/home/joakim/.local/lib/python3.10/site-packages/PyFunceble/checker/availability/base.py", line 900, in try_to_query_status_from_http_status_code
    lookup_result = self.http_status_code_query_tool.get_status_code()
  File "/home/joakim/.local/lib/python3.10/site-packages/PyFunceble/query/http_status_code.py", line 122, in wrapper
    return func(self, *args, **kwargs)  # pylint: disable=not-callable
  File "/home/joakim/.local/lib/python3.10/site-packages/PyFunceble/query/http_status_code.py", line 337, in get_status_code
    req = PyFunceble.factory.Requester.get(
  File "/home/joakim/.local/lib/python3.10/site-packages/PyFunceble/query/requests/requester.py", line 213, in wrapper
    req = getattr(self.session, verb.lower())(*args, **kwargs)
  File "/home/joakim/.local/lib/python3.10/site-packages/requests/sessions.py", line 542, in get
    return self.request('GET', url, **kwargs)
  File "/home/joakim/.local/lib/python3.10/site-packages/requests/sessions.py", line 529, in request
    resp = self.send(prep, **send_kwargs)
  File "/home/joakim/.local/lib/python3.10/site-packages/requests/sessions.py", line 645, in send
    r = adapter.send(request, **kwargs)
  File "/home/joakim/.local/lib/python3.10/site-packages/PyFunceble/query/requests/adapter/http.py", line 99, in send
    kwargs["proxies"] = self.fetch_proxy_from_pattern(parsed_url.hostname)
  File "/home/joakim/.local/lib/python3.10/site-packages/PyFunceble/query/requests/adapter/base.py", line 177, in fetch_proxy_from_pattern
    extension = self.extract_extension(subject)
  File "/home/joakim/.local/lib/python3.10/site-packages/PyFunceble/query/requests/adapter/base.py", line 133, in extract_extension
    last_point = subject.rindex(".")
ValueError: substring not found
[2022-03-21 01:13:13,313 | CRITICAL | ../../home/joakim/.local/lib/python3.10/site-packages/PyFunceble/cli/processes/workers/base.py:388@run | PPID9974:pyfunceble_tester_worker_19]:
Error while running target
Traceback (most recent call last):
  File "/home/joakim/.local/lib/python3.10/site-packages/PyFunceble/cli/processes/workers/base.py", line 373, in run
    result = self.target(consumed)
  File "/home/joakim/.local/lib/python3.10/site-packages/PyFunceble/cli/processes/workers/tester.py", line 292, in target
    .query_status()
  File "/home/joakim/.local/lib/python3.10/site-packages/PyFunceble/checker/base.py", line 157, in wrapper
    return func(self, *args, **kwargs)  # pylint: disable=not-callable
  File "/home/joakim/.local/lib/python3.10/site-packages/PyFunceble/checker/base.py", line 182, in wrapper
    result = func(self, *args, **kwargs)  # pylint: disable=not-callable
  File "/home/joakim/.local/lib/python3.10/site-packages/PyFunceble/checker/availability/domain_and_ip.py", line 109, in query_status
    result = query_object.query_status()
  File "/home/joakim/.local/lib/python3.10/site-packages/PyFunceble/checker/base.py", line 157, in wrapper
    return func(self, *args, **kwargs)  # pylint: disable=not-callable
  File "/home/joakim/.local/lib/python3.10/site-packages/PyFunceble/checker/base.py", line 182, in wrapper
    result = func(self, *args, **kwargs)  # pylint: disable=not-callable
  File "/home/joakim/.local/lib/python3.10/site-packages/PyFunceble/checker/availability/domain.py", line 168, in query_status
    self.try_to_query_status_from_http_status_code()
  File "/home/joakim/.local/lib/python3.10/site-packages/PyFunceble/checker/availability/base.py", line 900, in try_to_query_status_from_http_status_code
    lookup_result = self.http_status_code_query_tool.get_status_code()
  File "/home/joakim/.local/lib/python3.10/site-packages/PyFunceble/query/http_status_code.py", line 122, in wrapper
    return func(self, *args, **kwargs)  # pylint: disable=not-callable
  File "/home/joakim/.local/lib/python3.10/site-packages/PyFunceble/query/http_status_code.py", line 337, in get_status_code
    req = PyFunceble.factory.Requester.get(
  File "/home/joakim/.local/lib/python3.10/site-packages/PyFunceble/query/requests/requester.py", line 213, in wrapper
    req = getattr(self.session, verb.lower())(*args, **kwargs)
  File "/home/joakim/.local/lib/python3.10/site-packages/requests/sessions.py", line 542, in get
    return self.request('GET', url, **kwargs)
  File "/home/joakim/.local/lib/python3.10/site-packages/requests/sessions.py", line 529, in request
    resp = self.send(prep, **send_kwargs)
  File "/home/joakim/.local/lib/python3.10/site-packages/requests/sessions.py", line 667, in send
    history = [resp for resp in gen]
  File "/home/joakim/.local/lib/python3.10/site-packages/requests/sessions.py", line 667, in <listcomp>
    history = [resp for resp in gen]
  File "/home/joakim/.local/lib/python3.10/site-packages/requests/sessions.py", line 237, in resolve_redirects
    resp = self.send(
  File "/home/joakim/.local/lib/python3.10/site-packages/requests/sessions.py", line 645, in send
    r = adapter.send(request, **kwargs)
  File "/home/joakim/.local/lib/python3.10/site-packages/PyFunceble/query/requests/adapter/http.py", line 99, in send
    kwargs["proxies"] = self.fetch_proxy_from_pattern(parsed_url.hostname)
  File "/home/joakim/.local/lib/python3.10/site-packages/PyFunceble/query/requests/adapter/base.py", line 177, in fetch_proxy_from_pattern
    extension = self.extract_extension(subject)
  File "/home/joakim/.local/lib/python3.10/site-packages/PyFunceble/query/requests/adapter/base.py", line 133, in extract_extension
    last_point = subject.rindex(".")
ValueError: substring not found
[2022-03-21 02:01:01,204 | CRITICAL | ../../home/joakim/.local/lib/python3.10/site-packages/PyFunceble/cli/system/launcher.py:1004@start | PPID9834:MainProcess]:
Fatal error.
Traceback (most recent call last):
  File "/home/joakim/.local/lib/python3.10/site-packages/PyFunceble/cli/system/launcher.py", line 990, in start
    self.stop_and_wait_for_all_manager()
  File "/home/joakim/.local/lib/python3.10/site-packages/PyFunceble/cli/system/launcher.py", line 927, in stop_and_wait_for_all_manager
    self.tester_process_manager.wait()
  File "/home/joakim/.local/lib/python3.10/site-packages/PyFunceble/cli/processes/base.py", line 330, in wait
    raise worker_error
ValueError: substring not found
[2022-03-21 19:18:25,118 | CRITICAL | ../../home/joakim/.local/lib/python3.10/site-packages/PyFunceble/cli/processes/workers/base.py:388@run | PPID224335:pyfunceble_tester_worker_24]:
Error while running target
Traceback (most recent call last):
  File "/home/joakim/.local/lib/python3.10/site-packages/PyFunceble/cli/processes/workers/base.py", line 373, in run
    result = self.target(consumed)
  File "/home/joakim/.local/lib/python3.10/site-packages/PyFunceble/cli/processes/workers/tester.py", line 292, in target
    .query_status()
  File "/home/joakim/.local/lib/python3.10/site-packages/PyFunceble/checker/base.py", line 157, in wrapper
    return func(self, *args, **kwargs)  # pylint: disable=not-callable
  File "/home/joakim/.local/lib/python3.10/site-packages/PyFunceble/checker/base.py", line 182, in wrapper
    result = func(self, *args, **kwargs)  # pylint: disable=not-callable
  File "/home/joakim/.local/lib/python3.10/site-packages/PyFunceble/checker/availability/domain_and_ip.py", line 109, in query_status
    result = query_object.query_status()
  File "/home/joakim/.local/lib/python3.10/site-packages/PyFunceble/checker/base.py", line 157, in wrapper
    return func(self, *args, **kwargs)  # pylint: disable=not-callable
  File "/home/joakim/.local/lib/python3.10/site-packages/PyFunceble/checker/base.py", line 182, in wrapper
    result = func(self, *args, **kwargs)  # pylint: disable=not-callable
  File "/home/joakim/.local/lib/python3.10/site-packages/PyFunceble/checker/availability/domain.py", line 168, in query_status
    self.try_to_query_status_from_http_status_code()
  File "/home/joakim/.local/lib/python3.10/site-packages/PyFunceble/checker/availability/base.py", line 900, in try_to_query_status_from_http_status_code
    lookup_result = self.http_status_code_query_tool.get_status_code()
  File "/home/joakim/.local/lib/python3.10/site-packages/PyFunceble/query/http_status_code.py", line 122, in wrapper
    return func(self, *args, **kwargs)  # pylint: disable=not-callable
  File "/home/joakim/.local/lib/python3.10/site-packages/PyFunceble/query/http_status_code.py", line 337, in get_status_code
    req = PyFunceble.factory.Requester.get(
  File "/home/joakim/.local/lib/python3.10/site-packages/PyFunceble/query/requests/requester.py", line 213, in wrapper
    req = getattr(self.session, verb.lower())(*args, **kwargs)
  File "/home/joakim/.local/lib/python3.10/site-packages/requests/sessions.py", line 542, in get
    return self.request('GET', url, **kwargs)
  File "/home/joakim/.local/lib/python3.10/site-packages/requests/sessions.py", line 529, in request
    resp = self.send(prep, **send_kwargs)
  File "/home/joakim/.local/lib/python3.10/site-packages/requests/sessions.py", line 645, in send
    r = adapter.send(request, **kwargs)
  File "/home/joakim/.local/lib/python3.10/site-packages/PyFunceble/query/requests/adapter/http.py", line 99, in send
    kwargs["proxies"] = self.fetch_proxy_from_pattern(parsed_url.hostname)
  File "/home/joakim/.local/lib/python3.10/site-packages/PyFunceble/query/requests/adapter/base.py", line 177, in fetch_proxy_from_pattern
    extension = self.extract_extension(subject)
  File "/home/joakim/.local/lib/python3.10/site-packages/PyFunceble/query/requests/adapter/base.py", line 133, in extract_extension
    last_point = subject.rindex(".")
ValueError: substring not found
[2022-03-21 19:18:33,655 | CRITICAL | ../../home/joakim/.local/lib/python3.10/site-packages/PyFunceble/cli/processes/workers/base.py:388@run | PPID224327:pyfunceble_tester_worker_18]:
Error while running target
Traceback (most recent call last):
  File "/home/joakim/.local/lib/python3.10/site-packages/PyFunceble/cli/processes/workers/base.py", line 373, in run
    result = self.target(consumed)
  File "/home/joakim/.local/lib/python3.10/site-packages/PyFunceble/cli/processes/workers/tester.py", line 292, in target
    .query_status()
  File "/home/joakim/.local/lib/python3.10/site-packages/PyFunceble/checker/base.py", line 157, in wrapper
    return func(self, *args, **kwargs)  # pylint: disable=not-callable
  File "/home/joakim/.local/lib/python3.10/site-packages/PyFunceble/checker/base.py", line 182, in wrapper
    result = func(self, *args, **kwargs)  # pylint: disable=not-callable
  File "/home/joakim/.local/lib/python3.10/site-packages/PyFunceble/checker/availability/domain_and_ip.py", line 109, in query_status
    result = query_object.query_status()
  File "/home/joakim/.local/lib/python3.10/site-packages/PyFunceble/checker/base.py", line 157, in wrapper
    return func(self, *args, **kwargs)  # pylint: disable=not-callable
  File "/home/joakim/.local/lib/python3.10/site-packages/PyFunceble/checker/base.py", line 182, in wrapper
    result = func(self, *args, **kwargs)  # pylint: disable=not-callable
  File "/home/joakim/.local/lib/python3.10/site-packages/PyFunceble/checker/availability/domain.py", line 168, in query_status
    self.try_to_query_status_from_http_status_code()
  File "/home/joakim/.local/lib/python3.10/site-packages/PyFunceble/checker/availability/base.py", line 900, in try_to_query_status_from_http_status_code
    lookup_result = self.http_status_code_query_tool.get_status_code()
  File "/home/joakim/.local/lib/python3.10/site-packages/PyFunceble/query/http_status_code.py", line 122, in wrapper
    return func(self, *args, **kwargs)  # pylint: disable=not-callable
  File "/home/joakim/.local/lib/python3.10/site-packages/PyFunceble/query/http_status_code.py", line 337, in get_status_code
    req = PyFunceble.factory.Requester.get(
  File "/home/joakim/.local/lib/python3.10/site-packages/PyFunceble/query/requests/requester.py", line 213, in wrapper
    req = getattr(self.session, verb.lower())(*args, **kwargs)
  File "/home/joakim/.local/lib/python3.10/site-packages/requests/sessions.py", line 542, in get
    return self.request('GET', url, **kwargs)
  File "/home/joakim/.local/lib/python3.10/site-packages/requests/sessions.py", line 529, in request
    resp = self.send(prep, **send_kwargs)
  File "/home/joakim/.local/lib/python3.10/site-packages/requests/sessions.py", line 645, in send
    r = adapter.send(request, **kwargs)
  File "/home/joakim/.local/lib/python3.10/site-packages/PyFunceble/query/requests/adapter/http.py", line 99, in send
    kwargs["proxies"] = self.fetch_proxy_from_pattern(parsed_url.hostname)
  File "/home/joakim/.local/lib/python3.10/site-packages/PyFunceble/query/requests/adapter/base.py", line 177, in fetch_proxy_from_pattern
    extension = self.extract_extension(subject)
  File "/home/joakim/.local/lib/python3.10/site-packages/PyFunceble/query/requests/adapter/base.py", line 133, in extract_extension
    last_point = subject.rindex(".")
ValueError: substring not found
[2022-03-21 21:29:56,399 | CRITICAL | ../../home/joakim/.local/lib/python3.10/site-packages/PyFunceble/cli/processes/workers/base.py:388@run | PPID224351:pyfunceble_tester_worker_36]:
Error while running target
Traceback (most recent call last):
  File "/home/joakim/.local/lib/python3.10/site-packages/PyFunceble/cli/processes/workers/base.py", line 373, in run
    result = self.target(consumed)
  File "/home/joakim/.local/lib/python3.10/site-packages/PyFunceble/cli/processes/workers/tester.py", line 292, in target
    .query_status()
  File "/home/joakim/.local/lib/python3.10/site-packages/PyFunceble/checker/base.py", line 157, in wrapper
    return func(self, *args, **kwargs)  # pylint: disable=not-callable
  File "/home/joakim/.local/lib/python3.10/site-packages/PyFunceble/checker/base.py", line 182, in wrapper
    result = func(self, *args, **kwargs)  # pylint: disable=not-callable
  File "/home/joakim/.local/lib/python3.10/site-packages/PyFunceble/checker/availability/domain_and_ip.py", line 109, in query_status
    result = query_object.query_status()
  File "/home/joakim/.local/lib/python3.10/site-packages/PyFunceble/checker/base.py", line 157, in wrapper
    return func(self, *args, **kwargs)  # pylint: disable=not-callable
  File "/home/joakim/.local/lib/python3.10/site-packages/PyFunceble/checker/base.py", line 182, in wrapper
    result = func(self, *args, **kwargs)  # pylint: disable=not-callable
  File "/home/joakim/.local/lib/python3.10/site-packages/PyFunceble/checker/availability/domain.py", line 168, in query_status
    self.try_to_query_status_from_http_status_code()
  File "/home/joakim/.local/lib/python3.10/site-packages/PyFunceble/checker/availability/base.py", line 900, in try_to_query_status_from_http_status_code
    lookup_result = self.http_status_code_query_tool.get_status_code()
  File "/home/joakim/.local/lib/python3.10/site-packages/PyFunceble/query/http_status_code.py", line 122, in wrapper
    return func(self, *args, **kwargs)  # pylint: disable=not-callable
  File "/home/joakim/.local/lib/python3.10/site-packages/PyFunceble/query/http_status_code.py", line 337, in get_status_code
    req = PyFunceble.factory.Requester.get(
  File "/home/joakim/.local/lib/python3.10/site-packages/PyFunceble/query/requests/requester.py", line 213, in wrapper
    req = getattr(self.session, verb.lower())(*args, **kwargs)
  File "/home/joakim/.local/lib/python3.10/site-packages/requests/sessions.py", line 542, in get
    return self.request('GET', url, **kwargs)
  File "/home/joakim/.local/lib/python3.10/site-packages/requests/sessions.py", line 529, in request
    resp = self.send(prep, **send_kwargs)
  File "/home/joakim/.local/lib/python3.10/site-packages/requests/sessions.py", line 645, in send
    r = adapter.send(request, **kwargs)
  File "/home/joakim/.local/lib/python3.10/site-packages/PyFunceble/query/requests/adapter/http.py", line 99, in send
    kwargs["proxies"] = self.fetch_proxy_from_pattern(parsed_url.hostname)
  File "/home/joakim/.local/lib/python3.10/site-packages/PyFunceble/query/requests/adapter/base.py", line 177, in fetch_proxy_from_pattern
    extension = self.extract_extension(subject)
  File "/home/joakim/.local/lib/python3.10/site-packages/PyFunceble/query/requests/adapter/base.py", line 133, in extract_extension
    last_point = subject.rindex(".")
ValueError: substring not found
[2022-03-22 00:28:31,934 | CRITICAL | ../../home/joakim/.local/lib/python3.10/site-packages/PyFunceble/cli/processes/workers/base.py:388@run | PPID224363:pyfunceble_tester_worker_40]:
Error while running target
Traceback (most recent call last):
  File "/home/joakim/.local/lib/python3.10/site-packages/PyFunceble/cli/processes/workers/base.py", line 373, in run
    result = self.target(consumed)
  File "/home/joakim/.local/lib/python3.10/site-packages/PyFunceble/cli/processes/workers/tester.py", line 292, in target
    .query_status()
  File "/home/joakim/.local/lib/python3.10/site-packages/PyFunceble/checker/base.py", line 157, in wrapper
    return func(self, *args, **kwargs)  # pylint: disable=not-callable
  File "/home/joakim/.local/lib/python3.10/site-packages/PyFunceble/checker/base.py", line 182, in wrapper
    result = func(self, *args, **kwargs)  # pylint: disable=not-callable
  File "/home/joakim/.local/lib/python3.10/site-packages/PyFunceble/checker/availability/domain_and_ip.py", line 109, in query_status
    result = query_object.query_status()
  File "/home/joakim/.local/lib/python3.10/site-packages/PyFunceble/checker/base.py", line 157, in wrapper
    return func(self, *args, **kwargs)  # pylint: disable=not-callable
  File "/home/joakim/.local/lib/python3.10/site-packages/PyFunceble/checker/base.py", line 182, in wrapper
    result = func(self, *args, **kwargs)  # pylint: disable=not-callable
  File "/home/joakim/.local/lib/python3.10/site-packages/PyFunceble/checker/availability/domain.py", line 168, in query_status
    self.try_to_query_status_from_http_status_code()
  File "/home/joakim/.local/lib/python3.10/site-packages/PyFunceble/checker/availability/base.py", line 900, in try_to_query_status_from_http_status_code
    lookup_result = self.http_status_code_query_tool.get_status_code()
  File "/home/joakim/.local/lib/python3.10/site-packages/PyFunceble/query/http_status_code.py", line 122, in wrapper
    return func(self, *args, **kwargs)  # pylint: disable=not-callable
  File "/home/joakim/.local/lib/python3.10/site-packages/PyFunceble/query/http_status_code.py", line 337, in get_status_code
    req = PyFunceble.factory.Requester.get(
  File "/home/joakim/.local/lib/python3.10/site-packages/PyFunceble/query/requests/requester.py", line 213, in wrapper
    req = getattr(self.session, verb.lower())(*args, **kwargs)
  File "/home/joakim/.local/lib/python3.10/site-packages/requests/sessions.py", line 542, in get
    return self.request('GET', url, **kwargs)
  File "/home/joakim/.local/lib/python3.10/site-packages/requests/sessions.py", line 529, in request
    resp = self.send(prep, **send_kwargs)
  File "/home/joakim/.local/lib/python3.10/site-packages/requests/sessions.py", line 667, in send
    history = [resp for resp in gen]
  File "/home/joakim/.local/lib/python3.10/site-packages/requests/sessions.py", line 667, in <listcomp>
    history = [resp for resp in gen]
  File "/home/joakim/.local/lib/python3.10/site-packages/requests/sessions.py", line 237, in resolve_redirects
    resp = self.send(
  File "/home/joakim/.local/lib/python3.10/site-packages/requests/sessions.py", line 645, in send
    r = adapter.send(request, **kwargs)
  File "/home/joakim/.local/lib/python3.10/site-packages/PyFunceble/query/requests/adapter/https.py", line 99, in send
    kwargs["proxies"] = self.fetch_proxy_from_pattern(parsed_url.hostname)
  File "/home/joakim/.local/lib/python3.10/site-packages/PyFunceble/query/requests/adapter/base.py", line 172, in fetch_proxy_from_pattern
    raise TypeError(f"<subject> should be {str}, type(subject) given.")
TypeError: <subject> should be <class 'str'>, type(subject) given.
